Workbook

Sheet Independent Companies
A1: Company Name | B1: Status | C1: Ownership Type | D1: Year Founded | E1: Primary HQ City | F1: County | G1: Service Area (Counties) | H1: Sub-Region | I1: Property Types | J1: Targets Small Landlords | K1: Portfolio Size (Units) | L1: Principals / Owners | M1: Address | N1: Phone | O1: Website | P1: PM Software | Q1: Tenant Portal | R1: Tenant Payment Methods | S1: Mgmt Fee % | T1: Leasing Fee | U1: Renewal Fee | V1: Setup Fee | W1: Maintenance Markup | X1: Application Fee | Y1: Accepts Portable Screening | Z1: Credit Min | AA1: Income Ratio | AB1: Associations | AC1: Designations | AD1: Yelp Rating | AE1: Yelp Count | AF1: BBB Rating | AG1: Follow-up Flag | AH1: Notes
A2: Bell-Anderson & Associates | B2: Confirmed Independent | C2: Family-Owned | D2: 1972 | E2: Auburn | F2: King | G2: King | H2: South King | I2: SFR, Condo, Townhome, Multifamily, Commercial, HOA | J2: Yes | L2: Vickie Gaskill, Carrie Snyder, Jennifer Corp | M2: 4508 Auburn Way N Ste A-100, Auburn, WA 98002 | N2: (253) 852-8195 | O2: bell-anderson.net | P2: AppFolio (inferred); Rentvine for screening | Q2: Branded portal | R2: ACH, eCheck, Credit/Debit Card | Y2: No | AB2: NARPM, IREM, WSCAI, Kent Chamber | AC2: AMO, CRMC | AD2: 3.5 | AE2: 37 | AH2: 5 family members on staff
A3: SJA Property Management | B3: Confirmed Independent | C3: Founder-Owned | D3: 2009 | E3: Redmond | F3: King | G3: King | H3: Eastside | I3: SFR, Condo, Townhome, Small Multifamily | J3: Yes | K3: 1000 | L3: Devin Easterlin (CEO), Derek Bunyard, Alanna Farrington | M3: 16398 NE 85th St #200, Redmond, WA 98052 | N3: (425) 658-1920 | O3: propertymanagersseattle.com | P3: AppFolio | Q3: AppFolio Online Portal | R3: ACH, eCheck, Credit/Debit, Apple Pay | S3: 10% | T3: 60% (min $1,850) | U3: 25% (min $500) | V3: $385 SFR / $200 per unit MF | Y3: No | Z3: 650 | AA3: 3.0x | AB3: NARPM, RHAWA | AD3: 4.5 | AE3: 178 | AF3: A+ | AH3: Inc 5000 2016, 2017; PSBJ Hall of Fame 2019
A4: Real Property Associates (RPA) | B4: Confirmed Independent | C4: Founder-Owned | D4: 1991 | E4: Seattle | F4: King | G4: King, Snohomish | H4: Seattle, Eastside, Snohomish | I4: SFR, Small Multifamily | J4: Yes | M4: Seattle / Everett / Bellevue / Edmonds offices | N4: (206) 523-0300 | O4: rentseattle.com | P4: AppFolio | Q4: rentseattle.com | R4: ACH, eCheck, Credit/Debit, Apple Pay | Y4: No | AH4: 95% online rent payment adoption
A5: Brink Property Management | B5: Confirmed Independent | C5: Founder-Owned | D5: 1996 | E5: Bellevue | F5: King | G5: King, Snohomish | H5: Eastside, South Snohomish | I5: SFR, Multifamily | J5: Yes | L5: Dean Foggitt (President) | M5: 12011 Bel-Red Rd #101, Bellevue, WA 98005 | N5: (425) 458-4848 | P5: AppFolio (inferred) | Q5: Branded portal | R5: ACH, eCheck, Card | AE5: 94 | AH5: Annual revenue per D&B ~$960K
A6: Gregory Property Management | B6: Confirmed Independent | C6: Family-Owned | E6: Bothell | F6: King | G6: King, Snohomish | H6: Eastside, South Snohomish | I6: SFR | J6: Yes | L6: Brad Gregory | M6: Bothell, WA | P6: AppFolio (inferred) | Q6: Owner portal | R6: ACH, Card | S6: 7% start | T6: No leasing fee until placed | W6: 0% (transparent) | AH6: 30+ years; in-house maintenance; $1,500 pet damage guarantee
A7: AHC Property Management | B7: Confirmed Independent | C7: Family-Owned (Women-led) | D7: 1983 | E7: Redmond | F7: King | G7: King | H7: Eastside | I7: SFR, Condo | J7: Yes | L7: Mary, Danielle, Stacey | M7: Redmond / Bellevue area | P7: AppFolio (inferred) | R7: ACH, Card | AB7: Eastside Property Managers Association (original member)
A8: North Pacific Property Management | B8: Flag-Review | C8: Founder-Owned (large) | D8: 2000 | E8: Seattle | F8: King | G8: King, Snohomish | H8: Seattle, Eastside, Snohomish | I8: SFR | J8: Yes | L8: Joshua Fant (Founder) | M8: 2220 Queen Anne Ave N, Seattle, WA 98109 | N8: (206) 781-0186 | P8: AppFolio (inferred) | R8: ACH, Card | AE8: 179 | AG8: Scale check: 160 brokers, 23 PMs | AH8: PSBJ 100 Fastest Growing 6x
A9: Verraterra Property Management | B9: Confirmed Independent | C9: Unknown-Local | F9: King | G9: King, Snohomish | H9: Eastside, Snohomish, Seattle | I9: SFR, Multifamily, HOA, Condo | J9: Yes | M9: Bellevue area | AH9: 15+ years; broad service area
A10: Seattle Rental Management | B10: Confirmed Independent | C10: Boutique | E10: Seattle | F10: King | G10: King | H10: Queen Anne, Seattle | I10: SFR, Multifamily | J10: Yes | L10: Eric, Tiffany, Channel, Tia, Rob | M10: Queen Anne, Seattle | AH10: Boutique
A11: The Joseph Group | B11: Confirmed Independent | C11: Founder-Owned | E11: Seattle | F11: King | G11: King + 5 more (six-county) | H11: Seattle, Capitol Hill, NE | I11: SFR, Multifamily | J11: Yes | M11: Seattle | P11: AppFolio | Q11: AppFolio | R11: ACH, Card | Z11: 610 | AH11: In-house construction + brokerage; Eviction Protection Plan
A12: Cascade Management US | B12: Confirmed Independent | C12: Founder-Owned | D12: 1990 | E12: Seattle | F12: King | G12: King | H12: Capitol Hill, Seattle | I12: Multifamily | J12: Yes | K12: 25 | L12: Tammy Travers, Daniel Travers (MBA UW Foster) | M12: Seattle | AH12: Zillow Community Pillar; distinct from Portland Cascade Mgmt Inc.
A13: Emerald Door Property Management | B13: Confirmed Independent | C13: Founder-Owned | E13: Seattle | F13: King | G13: King | H13: Seattle, Eastside | I13: SFR, Multifamily | J13: Yes | L13: Ryan George Dosch (ARM) | M13: 5608 17th Ave NW #429, Seattle | AC13: ARM | AF13: A+ (accredited 2022) | AH13: Related to Emerald Heights PM at same address
A14: Full Service Property Management | B14: Confirmed Independent | C14: Local-Indep | F14: King | G14: King, Snohomish | H14: Multi-area | I14: SFR, Multifamily | J14: Yes | M14: Multi-area: Seattle, Edmonds, Lynnwood, Mukilteo, MI, Kent, Renton, Auburn, Federal Way, Snohomish | P14: AppFolio (inferred) | R14: ACH, Card | AA14: 2.5x (bank bal for 6mo leases) | AH14: 30+ years
A15: T-Square Properties | B15: Confirmed Independent | C15: Founder-Owned | D15: 1996 | E15: Mill Creek | F15: Snohomish | G15: King, Snohomish | H15: Mill Creek, North King, South Snoho | I15: SFR, Multifamily, Commercial | J15: Yes | M15: 15522 Main St, Mill Creek, WA | AB15: NARPM, IREM, NWMLS, CBA | AH15: 24+ years
A16: WPI Real Estate | B16: Confirmed Independent | C16: Family-Owned | D16: 1972 | E16: Seattle | F16: King | G16: King | H16: Seattle | I16: SFR, Multifamily, Commercial | J16: Yes | K16: 1000 | M16: 9500 Roosevelt Way NE #100, Seattle | P16: AppFolio | Q16: AppFolio EFT autopay | R16: ACH (EFT autopay), Card | AH16: Bilingual: Mandarin, Cantonese, Taiwanese, Spanish
A17: Ballard Realty | B17: Confirmed Independent | C17: Family-Owned | D17: 1973 | E17: Seattle | F17: King | G17: King | H17: Ballard, Seattle | I17: SFR, Condo, Townhome, Multifamily | J17: Yes | L17: Third generation family | M17: Ballard, Seattle | AH17: Storefront face-to-face service
A18: Cornell & Associates | B18: Flag-Review | C18: Family-Owned (large) | D18: 1972 | E18: Seattle | F18: King | G18: King | H18: Seattle (multi-neighborhood) | I18: Residential, Commercial | J18: Yes | K18: 6000 | L18: J. Blake Cornell (Pres), James Cornell (Owner) | M18: 2633 Eastlake Ave E #307, Seattle | AH18: Scale check: 6,000 units (large for independent)
A19: Walls Property Management | B19: Confirmed Independent | C19: Local-Indep | D19: 1960 | E19: Seattle | F19: King | G19: King | H19: Ballard, Fremont, Capitol Hill | I19: Multifamily | J19: No | M19: 5210 Russell Ave NW #100, Seattle | AH19: Multifamily Seattle since 1960s
A20: Gallagher Properties | B20: Confirmed Independent | C20: Local-Indep | E20: Seattle | F20: King | G20: King | H20: Seattle | I20: SFR, Multifamily, HOA | J20: Yes | M20: 1521 NW 54th St, Seattle | P20: Buildium | Q20: managebuilding.com | R20: ACH ($0.50), Card (2.95%) | AH20: 50+ years; family-style
A21: Dave Poletti & Associates | B21: Confirmed Independent | C21: Founder-Owned | D21: 1992 | E21: Seattle | F21: King | G21: King | H21: Seattle | I21: SFR, Condo, Multifamily | J21: Yes | L21: Dave Poletti (President) | M21: 1455 NW Leery Way #440, Seattle | AC21: CRMC | AF21: A+ (accredited 2007) | AH21: 33 years
A22: Madrona Real Estate | B22: Confirmed Independent | C22: Founder-Owned | E22: Seattle | F22: King | G22: King | H22: Capitol Hill, Shoreline | I22: HOA, Retail, Residential, Vacation | J22: Mixed | L22: Brad Augustine | M22: 1320 E Pike St, Seattle (+ Shoreline) | P22: Argus Financial Software | AH22: Also San Juan Islands vacation
A23: Pacific Crest Real Estate | B23: Confirmed Independent | C23: Founder-Owned | D23: 2003 | E23: Seattle | F23: King | G23: King | H23: Seattle, Eastside, South King | I23: Multifamily | J23: Yes | M23: 200 1st Ave W #520, Seattle 98119 | AE23: 53
A24: Seattle Property Management Associates (SPMA) | B24: Confirmed Independent | C24: Founder-Owned | D24: 1979 | E24: Seattle | F24: King | G24: King | H24: Seattle | I24: Multifamily, Commercial | J24: Yes | L24: Richard L. Kemp (Principal), Gudrun K. Snyder (Designated Broker) | M24: Seattle | P24: AppFolio | Q24: AppFolio | R24: ACH, Card
A25: Seattle's Property Management | B25: Confirmed Independent | C25: Local-Indep | E25: Seattle | F25: King | G25: King | H25: Seattle | I25: SFR, Condo, Small Multifamily | J25: Yes | M25: Seattle | P25: AppFolio | Q25: appfolio.com | R25: ACH, Card | AB25: NARPM, IREM | AF25: A+ | AH25: 25+ years
A26: GPS Renting | B26: Confirmed Independent | C26: Founder-Owned | E26: Bellevue | F26: King | G26: King | H26: Eastside | I26: SFR | J26: Yes | L26: Bryant Lu (Broker since 2014) | M26: Bellevue area | P26: AppFolio | Q26: AppFolio | R26: ACH, Card, Apple Pay | S26: 10% (subscription, no leasing fee) | T26: $0 (subscription) | AH26: Multilingual: Mandarin, Cantonese, English; 48hr comms credit; 60-day cancellation
A27: Sagareus Property Management | B27: Confirmed Independent | C27: Local-Indep | F27: King | G27: King, Pierce, Snohomish, Kitsap | H27: Greater Seattle, Eastside, South Sound, North Sound, Kitsap | I27: SFR, Multifamily | J27: Yes | M27: Greater Seattle | Z27: 650 | AA27: 2.5-3.0x | AH27: Multi-level AI-assisted screening; First-in-Time + Fair Chance compliant
A28: Icon Real Estate Services | B28: Confirmed Independent | C28: Founder-Owned | D28: 2015 | E28: Bellevue | F28: King | G28: King, Snohomish, Pierce, Grays Harbor, Kitsap | H28: Eastside, Seattle, South Sound, Snoho | I28: Multifamily | J28: Yes | M28: 10900 NE 4th St, Bellevue 98004 | Y28: No | AH28: Boutique multifamily
A29: Davis Property Management | B29: Confirmed Independent | C29: Local-Indep | E29: Bellevue | F29: King | G29: King | H29: Bellevue, Seattle, Puget Sound | I29: SFR, Condo, Townhome, Multifamily, Retail, Industrial, Commercial | J29: Yes | M29: Bellevue / Seattle | N29: (206) 999-3023 | P29: AppFolio (inferred) | R29: ACH, Card | AH29: Locally rooted
A30: 206 Property Management | B30: Confirmed Independent | C30: Family-Owned | E30: Seattle | F30: King | G30: King | H30: Seattle (Wallingford boutique) | I30: SFR, Small Multifamily, Studios-Triplex | J30: Yes | M30: Seattle | Y30: No | AH30: 1901 N 45th 40-unit boutique
A31: Haven Property Management | B31: Confirmed Independent | C31: Family-Owned | D31: 2015 | E31: Federal Way | F31: King | G31: King | H31: Federal Way, South King | I31: SFR | J31: Yes | L31: James A. Hernandez, Savannah Hernandez, Richard Hernandez | M31: 33600 6th Ave S #220, Federal Way 98003 | N31: (253) 214-7441 | O31: havenpropertymanagement.com | P31: AppFolio (inferred) | R31: ACH, Card | S31: 8% | T31: 100% (min $2,000); FSM 75% (min $1,200) | U31: $0 | V31: $0 | W31: 0% (no markup) | AD31: 3 | AG31: Mixed reviews | AH31: 131 Yelp / 257 Birdeye; mixed reviews on move-out charges
A32: Wilson Management | B32: Confirmed Independent | C32: Founder-Owned | F32: King | G32: King, Snohomish | H32: Eastside, South King, South Snoho | I32: SFR, Multifamily | J32: Yes | L32: Gary, Maria | M32: Multi-county | AH32: 40+ years
A33: MacPherson's Real Estate | B33: Confirmed Independent | C33: Local-Indep | F33: King | G33: King, Snohomish | H33: North King, South Snoho, North Snoho | I33: SFR, Multifamily | J33: Yes | M33: Multi-city WA
A34: Anchor Agency | B34: Confirmed Independent | C34: Founder-Owned | D34: 2020 | E34: Renton | F34: King | G34: King | H34: Renton, Seattle | I34: SFR, Multifamily, Commercial | J34: Yes | K34: 3650 | L34: Bayley Le, Gelly Lirio | M34: Renton/Seattle | AH34: Newer firm; 3,650 combined historical units
A35: Seattle Rental Group | B35: Confirmed Independent | C35: Local-Indep | E35: Seattle | F35: King | G35: King | H35: Seattle | I35: SFR, Multifamily | J35: Yes | M35: 2107 Elliott Ave #206, Seattle | P35: Intellirent (screening) | X35: $48 | Y35: No | AH35: 20+ years; zero-evictions claim
A36: Delta Property Management | B36: Confirmed Independent | C36: Founder-Owned | D36: 1990 | E36: Marysville | F36: Snohomish | G36: Snohomish | H36: Marysville, Lake Stevens, Everett | I36: SFR, Multifamily | J36: Yes | M36: Marysville | AH36: Snohomish County specialty
A37: Lifestyle Homes PM | B37: Confirmed Independent | C37: Local-Indep | E37: Mill Creek | F37: Snohomish | G37: King, Snohomish, Skagit | H37: Mill Creek, North | I37: SFR | J37: Yes | M37: 15522 Main St, Mill Creek (same bldg as T-Square)
A38: Infinity Properties International | B38: Confirmed Independent | C38: Local-Indep | E38: Arlington | F38: Snohomish | G38: Snohomish | H38: Arlington, Marysville, Stanwood, Lake Stevens | I38: SFR, Multifamily | J38: Yes | M38: Downtown Arlington, WA | AH38: 15+ years; 40+ pt biannual inspection
A39: Northwest Property Management Group | B39: Confirmed Independent | C39: Local-Indep | F39: Snohomish | G39: Snohomish | H39: Snohomish | I39: SFR, Multifamily | J39: Yes | M39: Snohomish County | AH39: 27+ years
A40: Real Estate Gladiators | B40: Confirmed Independent | C40: Boutique | E40: Monroe | F40: Snohomish | G40: King, Snohomish | H40: Monroe, Eastside | I40: SFR | J40: Yes | M40: Monroe, WA | AH40: Boutique
...

Sheet Excluded - PE & Institutional
A1: Company | B1: Exclusion Category | C1: Backer / Owner | D1: Scale | E1: Notes
A2: PURE Property Management (PURE HomeRiver) | B2: PE-backed | C2: Level Equity ($50M, Feb 2022), Bullock Capital, PGIM ($80M, Jan 2026) | D2: 40,000+ SFR / 80+ offices / 35+ states | E2: Merged with HomeRiver Jan 2026; acquired Mercer Island operation Mar 2025
A3: Mynd Management | B3: VC-backed / Institutional | C3: Institutional flat-fee national operator | D3: National
A4: Utopia Property Management | B4: Multistate Roll-up | D4: CA, WA, OR, NV | E4: Large multistate
A5: Doorstead | B5: VC-backed Proptech | C5: VC | D5: Multi-market
A6: Ziprent | B6: VC-backed Proptech | C6: VC | D6: Multi-market
A7: Belong Home | B7: VC-backed Proptech | C7: VC | D7: Multi-market
A8: Greystar | B8: Institutional | C8: Greystar Real Estate Partners | D8: Global
A9: Invitation Homes | B9: REIT | C9: Public REIT (INVH) | D9: National SFR REIT
A10: American Homes 4 Rent (AMH) | B10: REIT | C10: Public REIT (AMH) | D10: National SFR REIT
A11: Progress Residential | B11: Institutional SFR | C11: Pretium Partners | D11: National
A12: FirstKey Homes | B12: Institutional SFR | C12: Cerberus Capital | D12: National
A13: Mainstay Property Group | B13: Institutional | D13: National
A14: Tricon Residential | B14: REIT | C14: Tricon (acquired by Blackstone 2024) | D14: National
A15: Roofstock Property Management | B15: VC-backed Proptech | C15: VC | D15: National

Sheet Category Summary
A1: Summary by Status | D1: Summary by PM Software (substring match)
A3: Status | B3: Count | D3: Software | E3: Count (incl. inferred)
A4: Confirmed Independent | B4: =COUNTIF('Independent Companies'!B:B,"Confirmed Independent") -> 42 | D4: AppFolio | E4: =COUNTIF('Independent Companies'!P:P,"*AppFolio*") -> 15
A5: Flag-Review | B5: =COUNTIF('Independent Companies'!B:B,"Flag-Review") -> 8 | D5: Buildium | E5: =COUNTIF('Independent Companies'!P:P,"*Buildium*") -> 1
A6: Independent Franchise | B6: =COUNTIF('Independent Companies'!B:B,"Independent Franchise") -> 2 | D6: Rentvine | E6: =COUNTIF('Independent Companies'!P:P,"*Rentvine*") -> 1
A7: Total | B7: =SUM(B4:B6) -> 52 | D7: Intellirent | E7: =COUNTIF('Independent Companies'!P:P,"*Intellirent*") -> 1
D8: Argus | E8: =COUNTIF('Independent Companies'!P:P,"*Argus*") -> 1
A10: Summary by County
D11: Targets Small Landlords
A12: Primary County | B12: Count
A13: King | B13: =COUNTIF('Independent Companies'!F:F,"King") -> 44 | D13: Answer | E13: Count
A14: Snohomish | B14: =COUNTIF('Independent Companies'!F:F,"Snohomish") -> 8 | D14: Yes | E14: =COUNTIF('Independent Companies'!J:J,"Yes") -> 46
D15: No | E15: =COUNTIF('Independent Companies'!J:J,"No") -> 4
D16: Mixed | E16: =COUNTIF('Independent Companies'!J:J,"Mixed") -> 2
A17: Summary by Ownership Type
A19: Ownership Type | B19: Count
A20: Family-Owned | B20: =COUNTIF('Independent Companies'!C:C,"Family-Owned") -> 7
A21: Family-Owned (Women-led) | B21: =COUNTIF('Independent Companies'!C:C,"Family-Owned (Women-led)") -> 1
A22: Family-Owned (large) | B22: =COUNTIF('Independent Companies'!C:C,"Family-Owned (large)") -> 1
A23: Family-Owned (multigen) | B23: =COUNTIF('Independent Companies'!C:C,"Family-Owned (multigen)") -> 1
A24: Founder-Owned | B24: =COUNTIF('Independent Companies'!C:C,"Founder-Owned") -> 18
A25: Founder-Owned (large) | B25: =COUNTIF('Independent Companies'!C:C,"Founder-Owned (large)") -> 1
A26: Local-Indep | B26: =COUNTIF('Independent Companies'!C:C,"Local-Indep") -> 12
A27: Local-Indep (Women-led) | B27: =COUNTIF('Independent Companies'!C:C,"Local-Indep (Women-led)") -> 1
A28: Boutique | B28: =COUNTIF('Independent Companies'!C:C,"Boutique") -> 2
A29: Indep Franchise (Windermere) | B29: =COUNTIF('Independent Companies'!C:C,"Indep Franchise (Windermere)") -> 2
A30: Institutional Origin | B30: =COUNTIF('Independent Companies'!C:C,"Institutional Origin") -> 1
A31: Unknown | B31: =COUNTIF('Independent Companies'!C:C,"Unknown") -> 4
A32: Unknown-Local | B32: =COUNTIF('Independent Companies'!C:C,"Unknown-Local") -> 1

Sheet Legend
A1: Legend & Notes
A3: Status: Confirmed Independent | B3: Family- or founder-owned local firm, no PE/VC/REIT backing identified
A4: Status: Flag-Review | B4: Scale, ownership origin, or institutional client mix raises questions; needs follow-up
A5: Status: Independent Franchise | B5: Independently operated Windermere franchise; treat as independent for this market
A7: Confirmed Independent rows | B7: Green fill in Status column
A8: Flag-Review rows | B8: Yellow fill in Status column
A9: Independent Franchise rows | B9: Blue fill in Status column
A11: Source | B11: King_County_Snohomish_County_PM_Companies research dataset (project knowledge)
A12: Excluded sheet | B12: PE-backed, VC-backed, REIT, and institutional roll-ups; do NOT compete with as 'independent'
A13: Filter usage | B13: Click any column header arrow on the Independent Companies sheet to filter by county, ownership type, software, etc.
A14: Empty cells | B14: Field present in source but value not disclosed or not yet verified
